[2024-09-21T22:57:52.673+0000] {taskinstance.py:1956} INFO - Dependencies all met for dep_context=non-requeueable deps ti=<TaskInstance: dag_eval.getData manual__2024-09-21T22:57:48.721272+00:00 [queued]>
[2024-09-21T22:57:52.689+0000] {taskinstance.py:1956} INFO - Dependencies all met for dep_context=requeueable deps ti=<TaskInstance: dag_eval.getData manual__2024-09-21T22:57:48.721272+00:00 [queued]>
[2024-09-21T22:57:52.691+0000] {taskinstance.py:2170} INFO - Starting attempt 1 of 1
[2024-09-21T22:57:52.713+0000] {taskinstance.py:2191} INFO - Executing <Task(BashOperator): getData> on 2024-09-21 22:57:48.721272+00:00
[2024-09-21T22:57:52.723+0000] {standard_task_runner.py:60} INFO - Started process 118 to run task
[2024-09-21T22:57:52.728+0000] {standard_task_runner.py:87} INFO - Running: ['***', 'tasks', 'run', 'dag_eval', 'getData', 'manual__2024-09-21T22:57:48.721272+00:00', '--job-id', '7', '--raw', '--subdir', 'DAGS_FOLDER/main.py', '--cfg-path', '/tmp/tmpg9r4jww2']
[2024-09-21T22:57:52.731+0000] {standard_task_runner.py:88} INFO - Job 7: Subtask getData
[2024-09-21T22:57:52.751+0000] {warnings.py:109} WARNING - /home/***/.local/lib/python3.8/site-packages/***/settings.py:194: DeprecationWarning: The sql_alchemy_conn option in [core] has been moved to the sql_alchemy_conn option in [database] - the old setting has been used, but please update your config.
  SQL_ALCHEMY_CONN = conf.get("database", "SQL_ALCHEMY_CONN")

[2024-09-21T22:57:52.804+0000] {task_command.py:423} INFO - Running <TaskInstance: dag_eval.getData manual__2024-09-21T22:57:48.721272+00:00 [running]> on host cc45b92b61e2
[2024-09-21T22:57:52.933+0000] {taskinstance.py:2480} INFO - Exporting env vars: AIRFLOW_CTX_DAG_OWNER='***' AIRFLOW_CTX_DAG_ID='dag_eval' AIRFLOW_CTX_TASK_ID='getData' AIRFLOW_CTX_EXECUTION_DATE='2024-09-21T22:57:48.721272+00:00' AIRFLOW_CTX_TRY_NUMBER='1' AIRFLOW_CTX_DAG_RUN_ID='manual__2024-09-21T22:57:48.721272+00:00'
[2024-09-21T22:57:52.935+0000] {subprocess.py:63} INFO - Tmp dir root location: /tmp
[2024-09-21T22:57:52.936+0000] {subprocess.py:75} INFO - Running command: ['/usr/bin/bash', '-c', 'python3 /opt/***/dags/app/getWeatherData.py']
[2024-09-21T22:57:52.956+0000] {subprocess.py:86} INFO - Output:
[2024-09-21T22:57:54.717+0000] {subprocess.py:93} INFO - /home/***/.local/lib/python3.8/site-packages/***/configuration.py:812 DeprecationWarning: The sql_alchemy_conn option in [core] has been moved to the sql_alchemy_conn option in [database] - the old setting has been used, but please update your config.
[2024-09-21T22:57:54.722+0000] {subprocess.py:93} INFO - /home/***/.local/lib/python3.8/site-packages/***/configuration.py:738 DeprecationWarning: The sql_alchemy_conn option in [core] has been moved to the sql_alchemy_conn option in [database] - the old setting has been used, but please update your config.
[2024-09-21T22:57:54.725+0000] {subprocess.py:93} INFO - /home/***/.local/lib/python3.8/site-packages/***/settings.py:194 DeprecationWarning: The sql_alchemy_conn option in [core] has been moved to the sql_alchemy_conn option in [database] - the old setting has been used, but please update your config.
[2024-09-21T22:57:54.945+0000] {subprocess.py:93} INFO - /home/***/.local/lib/python3.8/site-packages/***/models/base.py:71 DeprecationWarning: The sql_alchemy_conn option in [core] has been moved to the sql_alchemy_conn option in [database] - the old setting has been used, but please update your config.
[2024-09-21T22:57:55.981+0000] {subprocess.py:93} INFO - [[34m2024-09-21T22:57:55.979+0000[0m] {[34mcrypto.py:[0m82} WARNING[0m - empty cryptography key - values will not be stored encrypted.[0m
[2024-09-21T22:58:00.628+0000] {subprocess.py:93} INFO - Traceback (most recent call last):
[2024-09-21T22:58:00.628+0000] {subprocess.py:93} INFO -   File "/opt/***/dags/app/getWeatherData.py", line 16, in <module>
[2024-09-21T22:58:00.629+0000] {subprocess.py:93} INFO -     time.sleep(60)
[2024-09-21T22:58:00.629+0000] {subprocess.py:93} INFO - NameError: name 'time' is not defined
[2024-09-21T22:58:01.009+0000] {subprocess.py:97} INFO - Command exited with return code 1
[2024-09-21T22:58:01.031+0000] {taskinstance.py:2698} ERROR - Task failed with exception
Traceback (most recent call last):
  File "/home/airflow/.local/lib/python3.8/site-packages/airflow/models/taskinstance.py", line 433, in _execute_task
    result = execute_callable(context=context, **execute_callable_kwargs)
  File "/home/airflow/.local/lib/python3.8/site-packages/airflow/operators/bash.py", line 212, in execute
    raise AirflowException(
airflow.exceptions.AirflowException: Bash command failed. The command returned a non-zero exit code 1.
[2024-09-21T22:58:01.038+0000] {taskinstance.py:1138} INFO - Marking task as FAILED. dag_id=dag_eval, task_id=getData, execution_date=20240921T225748, start_date=20240921T225752, end_date=20240921T225801
[2024-09-21T22:58:01.064+0000] {standard_task_runner.py:107} ERROR - Failed to execute job 7 for task getData (Bash command failed. The command returned a non-zero exit code 1.; 118)
[2024-09-21T22:58:01.092+0000] {local_task_job_runner.py:234} INFO - Task exited with return code 1
[2024-09-21T22:58:01.127+0000] {taskinstance.py:3280} INFO - 0 downstream tasks scheduled from follow-on schedule check
