[2024-09-21T23:41:21.153+0000] {taskinstance.py:1956} INFO - Dependencies all met for dep_context=non-requeueable deps ti=<TaskInstance: dag_eval.getData manual__2024-09-21T23:41:17.808239+00:00 [queued]>
[2024-09-21T23:41:21.182+0000] {taskinstance.py:1956} INFO - Dependencies all met for dep_context=requeueable deps ti=<TaskInstance: dag_eval.getData manual__2024-09-21T23:41:17.808239+00:00 [queued]>
[2024-09-21T23:41:21.183+0000] {taskinstance.py:2170} INFO - Starting attempt 1 of 1
[2024-09-21T23:41:21.216+0000] {taskinstance.py:2191} INFO - Executing <Task(PythonOperator): getData> on 2024-09-21 23:41:17.808239+00:00
[2024-09-21T23:41:21.229+0000] {standard_task_runner.py:60} INFO - Started process 1580 to run task
[2024-09-21T23:41:21.235+0000] {standard_task_runner.py:87} INFO - Running: ['***', 'tasks', 'run', 'dag_eval', 'getData', 'manual__2024-09-21T23:41:17.808239+00:00', '--job-id', '9', '--raw', '--subdir', 'DAGS_FOLDER/main.py', '--cfg-path', '/tmp/tmp48u__e89']
[2024-09-21T23:41:21.238+0000] {standard_task_runner.py:88} INFO - Job 9: Subtask getData
[2024-09-21T23:41:21.273+0000] {warnings.py:109} WARNING - /home/***/.local/lib/python3.8/site-packages/***/settings.py:194: DeprecationWarning: The sql_alchemy_conn option in [core] has been moved to the sql_alchemy_conn option in [database] - the old setting has been used, but please update your config.
  SQL_ALCHEMY_CONN = conf.get("database", "SQL_ALCHEMY_CONN")

[2024-09-21T23:41:21.357+0000] {task_command.py:423} INFO - Running <TaskInstance: dag_eval.getData manual__2024-09-21T23:41:17.808239+00:00 [running]> on host cc45b92b61e2
[2024-09-21T23:41:21.535+0000] {taskinstance.py:2480} INFO - Exporting env vars: AIRFLOW_CTX_DAG_OWNER='***' AIRFLOW_CTX_DAG_ID='dag_eval' AIRFLOW_CTX_TASK_ID='getData' AIRFLOW_CTX_EXECUTION_DATE='2024-09-21T23:41:17.808239+00:00' AIRFLOW_CTX_TRY_NUMBER='1' AIRFLOW_CTX_DAG_RUN_ID='manual__2024-09-21T23:41:17.808239+00:00'
[2024-09-21T23:41:21.537+0000] {taskinstance.py:2698} ERROR - Task failed with exception
Traceback (most recent call last):
  File "/home/airflow/.local/lib/python3.8/site-packages/airflow/models/taskinstance.py", line 433, in _execute_task
    result = execute_callable(context=context, **execute_callable_kwargs)
  File "/home/airflow/.local/lib/python3.8/site-packages/airflow/operators/python.py", line 199, in execute
    return_value = self.execute_callable()
  File "/home/airflow/.local/lib/python3.8/site-packages/airflow/operators/python.py", line 216, in execute_callable
    return self.python_callable(*self.op_args, **self.op_kwargs)
  File "/opt/airflow/dags/main.py", line 31, in getWeatherData
    data.append(requests.get(f"https://api.openweathermap.org/data/2.5/weather?q={citie}&appid={api}").content.decode('utf-8'))
NameError: name 'requests' is not defined
[2024-09-21T23:41:21.555+0000] {taskinstance.py:1138} INFO - Marking task as FAILED. dag_id=dag_eval, task_id=getData, execution_date=20240921T234117, start_date=20240921T234121, end_date=20240921T234121
[2024-09-21T23:41:21.581+0000] {standard_task_runner.py:107} ERROR - Failed to execute job 9 for task getData (name 'requests' is not defined; 1580)
[2024-09-21T23:41:21.611+0000] {local_task_job_runner.py:234} INFO - Task exited with return code 1
[2024-09-21T23:41:21.645+0000] {taskinstance.py:3280} INFO - 0 downstream tasks scheduled from follow-on schedule check
