[2024-09-21T22:49:59.713+0000] {taskinstance.py:1956} INFO - Dependencies all met for dep_context=non-requeueable deps ti=<TaskInstance: dag_eval.getData manual__2024-09-21T22:49:55.868895+00:00 [queued]>
[2024-09-21T22:49:59.735+0000] {taskinstance.py:1956} INFO - Dependencies all met for dep_context=requeueable deps ti=<TaskInstance: dag_eval.getData manual__2024-09-21T22:49:55.868895+00:00 [queued]>
[2024-09-21T22:49:59.736+0000] {taskinstance.py:2170} INFO - Starting attempt 1 of 1
[2024-09-21T22:49:59.772+0000] {taskinstance.py:2191} INFO - Executing <Task(BashOperator): getData> on 2024-09-21 22:49:55.868895+00:00
[2024-09-21T22:49:59.784+0000] {standard_task_runner.py:60} INFO - Started process 2288 to run task
[2024-09-21T22:49:59.788+0000] {standard_task_runner.py:87} INFO - Running: ['***', 'tasks', 'run', 'dag_eval', 'getData', 'manual__2024-09-21T22:49:55.868895+00:00', '--job-id', '4', '--raw', '--subdir', 'DAGS_FOLDER/main.py', '--cfg-path', '/tmp/tmpazkiqnjh']
[2024-09-21T22:49:59.791+0000] {standard_task_runner.py:88} INFO - Job 4: Subtask getData
[2024-09-21T22:49:59.821+0000] {warnings.py:109} WARNING - /home/***/.local/lib/python3.8/site-packages/***/settings.py:194: DeprecationWarning: The sql_alchemy_conn option in [core] has been moved to the sql_alchemy_conn option in [database] - the old setting has been used, but please update your config.
  SQL_ALCHEMY_CONN = conf.get("database", "SQL_ALCHEMY_CONN")

[2024-09-21T22:49:59.894+0000] {task_command.py:423} INFO - Running <TaskInstance: dag_eval.getData manual__2024-09-21T22:49:55.868895+00:00 [running]> on host cc45b92b61e2
[2024-09-21T22:50:00.043+0000] {taskinstance.py:2480} INFO - Exporting env vars: AIRFLOW_CTX_DAG_OWNER='***' AIRFLOW_CTX_DAG_ID='dag_eval' AIRFLOW_CTX_TASK_ID='getData' AIRFLOW_CTX_EXECUTION_DATE='2024-09-21T22:49:55.868895+00:00' AIRFLOW_CTX_TRY_NUMBER='1' AIRFLOW_CTX_DAG_RUN_ID='manual__2024-09-21T22:49:55.868895+00:00'
[2024-09-21T22:50:00.045+0000] {subprocess.py:63} INFO - Tmp dir root location: /tmp
[2024-09-21T22:50:00.045+0000] {subprocess.py:75} INFO - Running command: ['/usr/bin/bash', '-c', 'python3 app/getWeatherData.py']
[2024-09-21T22:50:00.066+0000] {subprocess.py:86} INFO - Output:
[2024-09-21T22:50:00.117+0000] {subprocess.py:93} INFO - python3: can't open file 'app/getWeatherData.py': [Errno 2] No such file or directory
[2024-09-21T22:50:00.123+0000] {subprocess.py:97} INFO - Command exited with return code 2
[2024-09-21T22:50:00.149+0000] {taskinstance.py:2698} ERROR - Task failed with exception
Traceback (most recent call last):
  File "/home/airflow/.local/lib/python3.8/site-packages/airflow/models/taskinstance.py", line 433, in _execute_task
    result = execute_callable(context=context, **execute_callable_kwargs)
  File "/home/airflow/.local/lib/python3.8/site-packages/airflow/operators/bash.py", line 212, in execute
    raise AirflowException(
airflow.exceptions.AirflowException: Bash command failed. The command returned a non-zero exit code 2.
[2024-09-21T22:50:00.157+0000] {taskinstance.py:1138} INFO - Marking task as FAILED. dag_id=dag_eval, task_id=getData, execution_date=20240921T224955, start_date=20240921T224959, end_date=20240921T225000
[2024-09-21T22:50:00.181+0000] {standard_task_runner.py:107} ERROR - Failed to execute job 4 for task getData (Bash command failed. The command returned a non-zero exit code 2.; 2288)
[2024-09-21T22:50:00.207+0000] {local_task_job_runner.py:234} INFO - Task exited with return code 1
[2024-09-21T22:50:00.237+0000] {taskinstance.py:3280} INFO - 0 downstream tasks scheduled from follow-on schedule check
