[2024-09-22T00:05:58.151+0000] {taskinstance.py:1956} INFO - Dependencies all met for dep_context=non-requeueable deps ti=<TaskInstance: dag_eval.20csv manual__2024-09-22T00:05:55.157615+00:00 [queued]>
[2024-09-22T00:05:58.169+0000] {taskinstance.py:1956} INFO - Dependencies all met for dep_context=requeueable deps ti=<TaskInstance: dag_eval.20csv manual__2024-09-22T00:05:55.157615+00:00 [queued]>
[2024-09-22T00:05:58.170+0000] {taskinstance.py:2170} INFO - Starting attempt 1 of 1
[2024-09-22T00:05:58.195+0000] {taskinstance.py:2191} INFO - Executing <Task(PythonOperator): 20csv> on 2024-09-22 00:05:55.157615+00:00
[2024-09-22T00:05:58.204+0000] {standard_task_runner.py:60} INFO - Started process 2428 to run task
[2024-09-22T00:05:58.209+0000] {standard_task_runner.py:87} INFO - Running: ['***', 'tasks', 'run', 'dag_eval', '20csv', 'manual__2024-09-22T00:05:55.157615+00:00', '--job-id', '18', '--raw', '--subdir', 'DAGS_FOLDER/main.py', '--cfg-path', '/tmp/tmp6zuf7bot']
[2024-09-22T00:05:58.212+0000] {standard_task_runner.py:88} INFO - Job 18: Subtask 20csv
[2024-09-22T00:05:58.233+0000] {warnings.py:109} WARNING - /home/***/.local/lib/python3.8/site-packages/***/settings.py:194: DeprecationWarning: The sql_alchemy_conn option in [core] has been moved to the sql_alchemy_conn option in [database] - the old setting has been used, but please update your config.
  SQL_ALCHEMY_CONN = conf.get("database", "SQL_ALCHEMY_CONN")

[2024-09-22T00:05:58.289+0000] {task_command.py:423} INFO - Running <TaskInstance: dag_eval.20csv manual__2024-09-22T00:05:55.157615+00:00 [running]> on host cc45b92b61e2
[2024-09-22T00:05:58.449+0000] {taskinstance.py:2480} INFO - Exporting env vars: AIRFLOW_CTX_DAG_OWNER='***' AIRFLOW_CTX_DAG_ID='dag_eval' AIRFLOW_CTX_TASK_ID='20csv' AIRFLOW_CTX_EXECUTION_DATE='2024-09-22T00:05:55.157615+00:00' AIRFLOW_CTX_TRY_NUMBER='1' AIRFLOW_CTX_DAG_RUN_ID='manual__2024-09-22T00:05:55.157615+00:00'
[2024-09-22T00:05:58.452+0000] {taskinstance.py:2698} ERROR - Task failed with exception
Traceback (most recent call last):
  File "/home/airflow/.local/lib/python3.8/site-packages/airflow/models/taskinstance.py", line 433, in _execute_task
    result = execute_callable(context=context, **execute_callable_kwargs)
  File "/home/airflow/.local/lib/python3.8/site-packages/airflow/operators/python.py", line 199, in execute
    return_value = self.execute_callable()
  File "/home/airflow/.local/lib/python3.8/site-packages/airflow/operators/python.py", line 216, in execute_callable
    return self.python_callable(*self.op_args, **self.op_kwargs)
  File "/opt/airflow/dags/main.py", line 40, in transform_data_into_csv
    files = sorted(os.listdir(parent_folder), reverse=True)
FileNotFoundError: [Errno 2] No such file or directory: 'app/raw_files'
[2024-09-22T00:05:58.467+0000] {taskinstance.py:1138} INFO - Marking task as FAILED. dag_id=dag_eval, task_id=20csv, execution_date=20240922T000555, start_date=20240922T000558, end_date=20240922T000558
[2024-09-22T00:05:58.489+0000] {standard_task_runner.py:107} ERROR - Failed to execute job 18 for task 20csv ([Errno 2] No such file or directory: 'app/raw_files'; 2428)
[2024-09-22T00:05:58.542+0000] {local_task_job_runner.py:234} INFO - Task exited with return code 1
[2024-09-22T00:05:58.580+0000] {taskinstance.py:3280} INFO - 0 downstream tasks scheduled from follow-on schedule check
