[2024-09-21T23:42:19.781+0000] {taskinstance.py:1956} INFO - Dependencies all met for dep_context=non-requeueable deps ti=<TaskInstance: dag_eval.getData manual__2024-09-21T23:42:16.445805+00:00 [queued]>
[2024-09-21T23:42:19.796+0000] {taskinstance.py:1956} INFO - Dependencies all met for dep_context=requeueable deps ti=<TaskInstance: dag_eval.getData manual__2024-09-21T23:42:16.445805+00:00 [queued]>
[2024-09-21T23:42:19.796+0000] {taskinstance.py:2170} INFO - Starting attempt 1 of 1
[2024-09-21T23:42:19.819+0000] {taskinstance.py:2191} INFO - Executing <Task(PythonOperator): getData> on 2024-09-21 23:42:16.445805+00:00
[2024-09-21T23:42:19.830+0000] {standard_task_runner.py:60} INFO - Started process 1620 to run task
[2024-09-21T23:42:19.834+0000] {standard_task_runner.py:87} INFO - Running: ['***', 'tasks', 'run', 'dag_eval', 'getData', 'manual__2024-09-21T23:42:16.445805+00:00', '--job-id', '11', '--raw', '--subdir', 'DAGS_FOLDER/main.py', '--cfg-path', '/tmp/tmp8ugssbj_']
[2024-09-21T23:42:19.837+0000] {standard_task_runner.py:88} INFO - Job 11: Subtask getData
[2024-09-21T23:42:19.865+0000] {warnings.py:109} WARNING - /home/***/.local/lib/python3.8/site-packages/***/settings.py:194: DeprecationWarning: The sql_alchemy_conn option in [core] has been moved to the sql_alchemy_conn option in [database] - the old setting has been used, but please update your config.
  SQL_ALCHEMY_CONN = conf.get("database", "SQL_ALCHEMY_CONN")

[2024-09-21T23:42:19.924+0000] {task_command.py:423} INFO - Running <TaskInstance: dag_eval.getData manual__2024-09-21T23:42:16.445805+00:00 [running]> on host cc45b92b61e2
[2024-09-21T23:42:20.133+0000] {taskinstance.py:2480} INFO - Exporting env vars: AIRFLOW_CTX_DAG_OWNER='***' AIRFLOW_CTX_DAG_ID='dag_eval' AIRFLOW_CTX_TASK_ID='getData' AIRFLOW_CTX_EXECUTION_DATE='2024-09-21T23:42:16.445805+00:00' AIRFLOW_CTX_TRY_NUMBER='1' AIRFLOW_CTX_DAG_RUN_ID='manual__2024-09-21T23:42:16.445805+00:00'
[2024-09-21T23:42:20.642+0000] {taskinstance.py:2698} ERROR - Task failed with exception
Traceback (most recent call last):
  File "/home/airflow/.local/lib/python3.8/site-packages/airflow/models/taskinstance.py", line 433, in _execute_task
    result = execute_callable(context=context, **execute_callable_kwargs)
  File "/home/airflow/.local/lib/python3.8/site-packages/airflow/operators/python.py", line 199, in execute
    return_value = self.execute_callable()
  File "/home/airflow/.local/lib/python3.8/site-packages/airflow/operators/python.py", line 216, in execute_callable
    return self.python_callable(*self.op_args, **self.op_kwargs)
  File "/opt/airflow/dags/main.py", line 35, in getWeatherData
    with open(f'app/raw_files/{datetime.datetime.now().strftime("%Y-%m-%d %H:%M")}.json', 'w') as json_file:
FileNotFoundError: [Errno 2] No such file or directory: 'app/raw_files/2024-09-21 23:42.json'
[2024-09-21T23:42:20.655+0000] {taskinstance.py:1138} INFO - Marking task as FAILED. dag_id=dag_eval, task_id=getData, execution_date=20240921T234216, start_date=20240921T234219, end_date=20240921T234220
[2024-09-21T23:42:20.676+0000] {standard_task_runner.py:107} ERROR - Failed to execute job 11 for task getData ([Errno 2] No such file or directory: 'app/raw_files/2024-09-21 23:42.json'; 1620)
[2024-09-21T23:42:20.693+0000] {local_task_job_runner.py:234} INFO - Task exited with return code 1
[2024-09-21T23:42:20.726+0000] {taskinstance.py:3280} INFO - 0 downstream tasks scheduled from follow-on schedule check
