[2024-09-22T00:08:43.506+0000] {taskinstance.py:1956} INFO - Dependencies all met for dep_context=non-requeueable deps ti=<TaskInstance: dag_eval.20csv manual__2024-09-22T00:08:40.697040+00:00 [queued]>
[2024-09-22T00:08:43.520+0000] {taskinstance.py:1956} INFO - Dependencies all met for dep_context=requeueable deps ti=<TaskInstance: dag_eval.20csv manual__2024-09-22T00:08:40.697040+00:00 [queued]>
[2024-09-22T00:08:43.521+0000] {taskinstance.py:2170} INFO - Starting attempt 1 of 1
[2024-09-22T00:08:43.543+0000] {taskinstance.py:2191} INFO - Executing <Task(PythonOperator): 20csv> on 2024-09-22 00:08:40.697040+00:00
[2024-09-22T00:08:43.552+0000] {standard_task_runner.py:60} INFO - Started process 2528 to run task
[2024-09-22T00:08:43.561+0000] {standard_task_runner.py:87} INFO - Running: ['***', 'tasks', 'run', 'dag_eval', '20csv', 'manual__2024-09-22T00:08:40.697040+00:00', '--job-id', '22', '--raw', '--subdir', 'DAGS_FOLDER/main.py', '--cfg-path', '/tmp/tmph206wznc']
[2024-09-22T00:08:43.564+0000] {standard_task_runner.py:88} INFO - Job 22: Subtask 20csv
[2024-09-22T00:08:43.588+0000] {warnings.py:109} WARNING - /home/***/.local/lib/python3.8/site-packages/***/settings.py:194: DeprecationWarning: The sql_alchemy_conn option in [core] has been moved to the sql_alchemy_conn option in [database] - the old setting has been used, but please update your config.
  SQL_ALCHEMY_CONN = conf.get("database", "SQL_ALCHEMY_CONN")

[2024-09-22T00:08:43.645+0000] {task_command.py:423} INFO - Running <TaskInstance: dag_eval.20csv manual__2024-09-22T00:08:40.697040+00:00 [running]> on host cc45b92b61e2
[2024-09-22T00:08:43.813+0000] {taskinstance.py:2480} INFO - Exporting env vars: AIRFLOW_CTX_DAG_OWNER='***' AIRFLOW_CTX_DAG_ID='dag_eval' AIRFLOW_CTX_TASK_ID='20csv' AIRFLOW_CTX_EXECUTION_DATE='2024-09-22T00:08:40.697040+00:00' AIRFLOW_CTX_TRY_NUMBER='1' AIRFLOW_CTX_DAG_RUN_ID='manual__2024-09-22T00:08:40.697040+00:00'
[2024-09-22T00:08:43.818+0000] {taskinstance.py:2698} ERROR - Task failed with exception
Traceback (most recent call last):
  File "/home/airflow/.local/lib/python3.8/site-packages/airflow/models/taskinstance.py", line 433, in _execute_task
    result = execute_callable(context=context, **execute_callable_kwargs)
  File "/home/airflow/.local/lib/python3.8/site-packages/airflow/operators/python.py", line 199, in execute
    return_value = self.execute_callable()
  File "/home/airflow/.local/lib/python3.8/site-packages/airflow/operators/python.py", line 216, in execute_callable
    return self.python_callable(*self.op_args, **self.op_kwargs)
  File "/opt/airflow/dags/main.py", line 59, in transform_data_into_csv
    df = pd.DataFrame(dfs)
NameError: name 'pd' is not defined
[2024-09-22T00:08:43.832+0000] {taskinstance.py:1138} INFO - Marking task as FAILED. dag_id=dag_eval, task_id=20csv, execution_date=20240922T000840, start_date=20240922T000843, end_date=20240922T000843
[2024-09-22T00:08:43.855+0000] {standard_task_runner.py:107} ERROR - Failed to execute job 22 for task 20csv (name 'pd' is not defined; 2528)
[2024-09-22T00:08:43.897+0000] {local_task_job_runner.py:234} INFO - Task exited with return code 1
[2024-09-22T00:08:43.936+0000] {taskinstance.py:3280} INFO - 0 downstream tasks scheduled from follow-on schedule check
