[2024-09-21T22:52:21.020+0000] {taskinstance.py:1956} INFO - Dependencies all met for dep_context=non-requeueable deps ti=<TaskInstance: dag_eval.getData manual__2024-09-21T22:52:17.366537+00:00 [queued]>
[2024-09-21T22:52:21.038+0000] {taskinstance.py:1956} INFO - Dependencies all met for dep_context=requeueable deps ti=<TaskInstance: dag_eval.getData manual__2024-09-21T22:52:17.366537+00:00 [queued]>
[2024-09-21T22:52:21.039+0000] {taskinstance.py:2170} INFO - Starting attempt 1 of 1
[2024-09-21T22:52:21.086+0000] {taskinstance.py:2191} INFO - Executing <Task(BashOperator): getData> on 2024-09-21 22:52:17.366537+00:00
[2024-09-21T22:52:21.097+0000] {standard_task_runner.py:60} INFO - Started process 2373 to run task
[2024-09-21T22:52:21.102+0000] {standard_task_runner.py:87} INFO - Running: ['***', 'tasks', 'run', 'dag_eval', 'getData', 'manual__2024-09-21T22:52:17.366537+00:00', '--job-id', '5', '--raw', '--subdir', 'DAGS_FOLDER/main.py', '--cfg-path', '/tmp/tmplh2onjuz']
[2024-09-21T22:52:21.106+0000] {standard_task_runner.py:88} INFO - Job 5: Subtask getData
[2024-09-21T22:52:21.149+0000] {warnings.py:109} WARNING - /home/***/.local/lib/python3.8/site-packages/***/settings.py:194: DeprecationWarning: The sql_alchemy_conn option in [core] has been moved to the sql_alchemy_conn option in [database] - the old setting has been used, but please update your config.
  SQL_ALCHEMY_CONN = conf.get("database", "SQL_ALCHEMY_CONN")

[2024-09-21T22:52:21.259+0000] {task_command.py:423} INFO - Running <TaskInstance: dag_eval.getData manual__2024-09-21T22:52:17.366537+00:00 [running]> on host cc45b92b61e2
[2024-09-21T22:52:21.520+0000] {taskinstance.py:2480} INFO - Exporting env vars: AIRFLOW_CTX_DAG_OWNER='***' AIRFLOW_CTX_DAG_ID='dag_eval' AIRFLOW_CTX_TASK_ID='getData' AIRFLOW_CTX_EXECUTION_DATE='2024-09-21T22:52:17.366537+00:00' AIRFLOW_CTX_TRY_NUMBER='1' AIRFLOW_CTX_DAG_RUN_ID='manual__2024-09-21T22:52:17.366537+00:00'
[2024-09-21T22:52:21.523+0000] {subprocess.py:63} INFO - Tmp dir root location: /tmp
[2024-09-21T22:52:21.546+0000] {subprocess.py:75} INFO - Running command: ['/usr/bin/bash', '-c', 'python3 /opt/***/dags../app/getWeatherData.py']
[2024-09-21T22:52:21.571+0000] {subprocess.py:86} INFO - Output:
[2024-09-21T22:52:21.623+0000] {subprocess.py:93} INFO - python3: can't open file '/opt/***/dags../app/getWeatherData.py': [Errno 2] No such file or directory
[2024-09-21T22:52:21.628+0000] {subprocess.py:97} INFO - Command exited with return code 2
[2024-09-21T22:52:21.645+0000] {taskinstance.py:2698} ERROR - Task failed with exception
Traceback (most recent call last):
  File "/home/airflow/.local/lib/python3.8/site-packages/airflow/models/taskinstance.py", line 433, in _execute_task
    result = execute_callable(context=context, **execute_callable_kwargs)
  File "/home/airflow/.local/lib/python3.8/site-packages/airflow/operators/bash.py", line 212, in execute
    raise AirflowException(
airflow.exceptions.AirflowException: Bash command failed. The command returned a non-zero exit code 2.
[2024-09-21T22:52:21.651+0000] {taskinstance.py:1138} INFO - Marking task as FAILED. dag_id=dag_eval, task_id=getData, execution_date=20240921T225217, start_date=20240921T225221, end_date=20240921T225221
[2024-09-21T22:52:21.682+0000] {standard_task_runner.py:107} ERROR - Failed to execute job 5 for task getData (Bash command failed. The command returned a non-zero exit code 2.; 2373)
[2024-09-21T22:52:21.707+0000] {local_task_job_runner.py:234} INFO - Task exited with return code 1
[2024-09-21T22:52:21.755+0000] {taskinstance.py:3280} INFO - 0 downstream tasks scheduled from follow-on schedule check
